[2025-03-21 14:07:33] ERROR:asyncio:Exception in callback _ProactorBasePipeTransport._call_connection_lost(None)
handle: <Handle _ProactorBasePipeTransport._call_connection_lost(None)>
Traceback (most recent call last):
  File "C:\Users\BenjaminLi\AppData\Local\Programs\Python\Python312\Lib\asyncio\events.py", line 88, in _run
    self._context.run(self._callback, *self._args)
  File "C:\Users\BenjaminLi\AppData\Local\Programs\Python\Python312\Lib\asyncio\proactor_events.py", line 165, in _call_connection_lost
    self._sock.shutdown(socket.SHUT_RDWR)
ConnectionResetError: [WinError 10054] An existing connection was forcibly closed by the remote host
[2025-03-21 14:07:33] ERROR:asyncio:Exception in callback _ProactorBasePipeTransport._call_connection_lost(None)
handle: <Handle _ProactorBasePipeTransport._call_connection_lost(None)>
Traceback (most recent call last):
  File "C:\Users\BenjaminLi\AppData\Local\Programs\Python\Python312\Lib\asyncio\events.py", line 88, in _run
    self._context.run(self._callback, *self._args)
  File "C:\Users\BenjaminLi\AppData\Local\Programs\Python\Python312\Lib\asyncio\proactor_events.py", line 165, in _call_connection_lost
    self._sock.shutdown(socket.SHUT_RDWR)
ConnectionResetError: [WinError 10054] An existing connection was forcibly closed by the remote host
[2025-03-21 14:07:33] ERROR:asyncio:Exception in callback _ProactorBasePipeTransport._call_connection_lost(None)
handle: <Handle _ProactorBasePipeTransport._call_connection_lost(None)>
Traceback (most recent call last):
  File "C:\Users\BenjaminLi\AppData\Local\Programs\Python\Python312\Lib\asyncio\events.py", line 88, in _run
    self._context.run(self._callback, *self._args)
  File "C:\Users\BenjaminLi\AppData\Local\Programs\Python\Python312\Lib\asyncio\proactor_events.py", line 165, in _call_connection_lost
    self._sock.shutdown(socket.SHUT_RDWR)
ConnectionResetError: [WinError 10054] An existing connection was forcibly closed by the remote host
[2025-03-21 14:07:33] ERROR:asyncio:Exception in callback _ProactorBasePipeTransport._call_connection_lost(None)
handle: <Handle _ProactorBasePipeTransport._call_connection_lost(None)>
Traceback (most recent call last):
  File "C:\Users\BenjaminLi\AppData\Local\Programs\Python\Python312\Lib\asyncio\events.py", line 88, in _run
    self._context.run(self._callback, *self._args)
  File "C:\Users\BenjaminLi\AppData\Local\Programs\Python\Python312\Lib\asyncio\proactor_events.py", line 165, in _call_connection_lost
    self._sock.shutdown(socket.SHUT_RDWR)
ConnectionResetError: [WinError 10054] An existing connection was forcibly closed by the remote host
[2025-03-21 14:07:33] ERROR:asyncio:Exception in callback _ProactorBasePipeTransport._call_connection_lost(None)
handle: <Handle _ProactorBasePipeTransport._call_connection_lost(None)>
Traceback (most recent call last):
  File "C:\Users\BenjaminLi\AppData\Local\Programs\Python\Python312\Lib\asyncio\events.py", line 88, in _run
    self._context.run(self._callback, *self._args)
  File "C:\Users\BenjaminLi\AppData\Local\Programs\Python\Python312\Lib\asyncio\proactor_events.py", line 165, in _call_connection_lost
    self._sock.shutdown(socket.SHUT_RDWR)
ConnectionResetError: [WinError 10054] An existing connection was forcibly closed by the remote host
[2025-03-21 14:07:33] ERROR:asyncio:Exception in callback _ProactorBasePipeTransport._call_connection_lost(None)
handle: <Handle _ProactorBasePipeTransport._call_connection_lost(None)>
Traceback (most recent call last):
  File "C:\Users\BenjaminLi\AppData\Local\Programs\Python\Python312\Lib\asyncio\events.py", line 88, in _run
    self._context.run(self._callback, *self._args)
  File "C:\Users\BenjaminLi\AppData\Local\Programs\Python\Python312\Lib\asyncio\proactor_events.py", line 165, in _call_connection_lost
    self._sock.shutdown(socket.SHUT_RDWR)
ConnectionResetError: [WinError 10054] An existing connection was forcibly closed by the remote host
[2025-03-21 14:07:33] ERROR:asyncio:Exception in callback _ProactorBasePipeTransport._call_connection_lost(None)
handle: <Handle _ProactorBasePipeTransport._call_connection_lost(None)>
Traceback (most recent call last):
  File "C:\Users\BenjaminLi\AppData\Local\Programs\Python\Python312\Lib\asyncio\events.py", line 88, in _run
    self._context.run(self._callback, *self._args)
  File "C:\Users\BenjaminLi\AppData\Local\Programs\Python\Python312\Lib\asyncio\proactor_events.py", line 165, in _call_connection_lost
    self._sock.shutdown(socket.SHUT_RDWR)
ConnectionResetError: [WinError 10054] An existing connection was forcibly closed by the remote host
[2025-03-21 14:07:33] ERROR:asyncio:Exception in callback _ProactorBasePipeTransport._call_connection_lost(None)
handle: <Handle _ProactorBasePipeTransport._call_connection_lost(None)>
Traceback (most recent call last):
  File "C:\Users\BenjaminLi\AppData\Local\Programs\Python\Python312\Lib\asyncio\events.py", line 88, in _run
    self._context.run(self._callback, *self._args)
  File "C:\Users\BenjaminLi\AppData\Local\Programs\Python\Python312\Lib\asyncio\proactor_events.py", line 165, in _call_connection_lost
    self._sock.shutdown(socket.SHUT_RDWR)
ConnectionResetError: [WinError 10054] An existing connection was forcibly closed by the remote host
[2025-03-21 14:07:33] ERROR:asyncio:Exception in callback _ProactorBasePipeTransport._call_connection_lost(None)
handle: <Handle _ProactorBasePipeTransport._call_connection_lost(None)>
Traceback (most recent call last):
  File "C:\Users\BenjaminLi\AppData\Local\Programs\Python\Python312\Lib\asyncio\events.py", line 88, in _run
    self._context.run(self._callback, *self._args)
  File "C:\Users\BenjaminLi\AppData\Local\Programs\Python\Python312\Lib\asyncio\proactor_events.py", line 165, in _call_connection_lost
    self._sock.shutdown(socket.SHUT_RDWR)
ConnectionResetError: [WinError 10054] An existing connection was forcibly closed by the remote host
[2025-03-21 14:07:33] ERROR:asyncio:Exception in callback _ProactorBasePipeTransport._call_connection_lost(None)
handle: <Handle _ProactorBasePipeTransport._call_connection_lost(None)>
Traceback (most recent call last):
  File "C:\Users\BenjaminLi\AppData\Local\Programs\Python\Python312\Lib\asyncio\events.py", line 88, in _run
    self._context.run(self._callback, *self._args)
  File "C:\Users\BenjaminLi\AppData\Local\Programs\Python\Python312\Lib\asyncio\proactor_events.py", line 165, in _call_connection_lost
    self._sock.shutdown(socket.SHUT_RDWR)
ConnectionResetError: [WinError 10054] An existing connection was forcibly closed by the remote host
[2025-03-21 14:07:33] ERROR:asyncio:Exception in callback _ProactorBasePipeTransport._call_connection_lost(None)
handle: <Handle _ProactorBasePipeTransport._call_connection_lost(None)>
Traceback (most recent call last):
  File "C:\Users\BenjaminLi\AppData\Local\Programs\Python\Python312\Lib\asyncio\events.py", line 88, in _run
    self._context.run(self._callback, *self._args)
  File "C:\Users\BenjaminLi\AppData\Local\Programs\Python\Python312\Lib\asyncio\proactor_events.py", line 165, in _call_connection_lost
    self._sock.shutdown(socket.SHUT_RDWR)
ConnectionResetError: [WinError 10054] An existing connection was forcibly closed by the remote host
[2025-03-21 14:07:33] ERROR:asyncio:Exception in callback _ProactorBasePipeTransport._call_connection_lost(None)
handle: <Handle _ProactorBasePipeTransport._call_connection_lost(None)>
Traceback (most recent call last):
  File "C:\Users\BenjaminLi\AppData\Local\Programs\Python\Python312\Lib\asyncio\events.py", line 88, in _run
    self._context.run(self._callback, *self._args)
  File "C:\Users\BenjaminLi\AppData\Local\Programs\Python\Python312\Lib\asyncio\proactor_events.py", line 165, in _call_connection_lost
    self._sock.shutdown(socket.SHUT_RDWR)
ConnectionResetError: [WinError 10054] An existing connection was forcibly closed by the remote host
[2025-03-21 14:07:33] ERROR:asyncio:Exception in callback _ProactorBasePipeTransport._call_connection_lost(None)
handle: <Handle _ProactorBasePipeTransport._call_connection_lost(None)>
Traceback (most recent call last):
  File "C:\Users\BenjaminLi\AppData\Local\Programs\Python\Python312\Lib\asyncio\events.py", line 88, in _run
    self._context.run(self._callback, *self._args)
  File "C:\Users\BenjaminLi\AppData\Local\Programs\Python\Python312\Lib\asyncio\proactor_events.py", line 165, in _call_connection_lost
    self._sock.shutdown(socket.SHUT_RDWR)
ConnectionResetError: [WinError 10054] An existing connection was forcibly closed by the remote host
[2025-03-21 14:46:41] ERROR:__main__:Cannot connect to host 82.push2.eastmoney.com:443 ssl:default [The semaphore timeout period has expired]
Traceback (most recent call last):
  File "C:\aqua\firestone-lab\venv\Lib\site-packages\aiohttp\connector.py", line 1116, in _wrap_create_connection
    sock = await aiohappyeyeballs.start_connection(
           ^^^^^^^^^^^^^^^^^^^^^^^^^^^^^^^^^^^^^^^^
  File "C:\aqua\firestone-lab\venv\Lib\site-packages\aiohappyeyeballs\impl.py", line 122, in start_connection
    raise first_exception
  File "C:\aqua\firestone-lab\venv\Lib\site-packages\aiohappyeyeballs\impl.py", line 73, in start_connection
    sock = await _connect_sock(
           ^^^^^^^^^^^^^^^^^^^^
  File "C:\aqua\firestone-lab\venv\Lib\site-packages\aiohappyeyeballs\impl.py", line 208, in _connect_sock
    await loop.sock_connect(sock, address)
  File "C:\Users\BenjaminLi\AppData\Local\Programs\Python\Python312\Lib\asyncio\proactor_events.py", line 729, in sock_connect
    return await self._proactor.connect(sock, address)
           ^^^^^^^^^^^^^^^^^^^^^^^^^^^^^^^^^^^^^^^^^^^
  File "C:\Users\BenjaminLi\AppData\Local\Programs\Python\Python312\Lib\asyncio\windows_events.py", line 803, in _poll
    value = callback(transferred, key, ov)
            ^^^^^^^^^^^^^^^^^^^^^^^^^^^^^^
  File "C:\Users\BenjaminLi\AppData\Local\Programs\Python\Python312\Lib\asyncio\windows_events.py", line 599, in finish_connect
    ov.getresult()
OSError: [WinError 121] The semaphore timeout period has expired

The above exception was the direct cause of the following exception:

Traceback (most recent call last):
  File "C:\aqua\firestone-lab\src\app.py", line 29, in <module>
    if self.base.is_trade_enable():
                            ^^^^^^^^
  File "C:\aqua\firestone-lab\venv\Lib\site-packages\akshare\stock_a\stock_zh_a_spot.py", line 229, in stock_zh_a_spot_em
    return asyncio.run(stock_zh_a_spot_em_async())
           ^^^^^^^^^^^^^^^^^^^^^^^^^^^^^^^^^^^^^^^
  File "C:\Users\BenjaminLi\AppData\Local\Programs\Python\Python312\Lib\asyncio\runners.py", line 194, in run
    return runner.run(main)
           ^^^^^^^^^^^^^^^^
  File "C:\Users\BenjaminLi\AppData\Local\Programs\Python\Python312\Lib\asyncio\runners.py", line 118, in run
    return self._loop.run_until_complete(task)
           ^^^^^^^^^^^^^^^^^^^^^^^^^^^^^^^^^^^
  File "C:\Users\BenjaminLi\AppData\Local\Programs\Python\Python312\Lib\asyncio\base_events.py", line 687, in run_until_complete
    return future.result()
           ^^^^^^^^^^^^^^^
  File "C:\aqua\firestone-lab\venv\Lib\site-packages\akshare\stock_a\stock_zh_a_spot.py", line 218, in stock_zh_a_spot_em_async
    results = await fetch_all_pages_async(url, params)
              ^^^^^^^^^^^^^^^^^^^^^^^^^^^^^^^^^^^^^^^^
  File "C:\aqua\firestone-lab\venv\Lib\site-packages\akshare\stock_a\stock_zh_a_spot.py", line 53, in fetch_all_pages_async
    results = await asyncio.gather(*tasks)
              ^^^^^^^^^^^^^^^^^^^^^^^^^^^^
  File "C:\aqua\firestone-lab\venv\Lib\site-packages\akshare\stock_a\stock_zh_a_spot.py", line 21, in fetch_single_page
    async with session.get(url, params=params) as response:
  File "C:\aqua\firestone-lab\venv\Lib\site-packages\aiohttp\client.py", line 1425, in __aenter__
    self._resp: _RetType = await self._coro
                           ^^^^^^^^^^^^^^^^
  File "C:\aqua\firestone-lab\venv\Lib\site-packages\aiohttp\client.py", line 703, in _request
    conn = await self._connector.connect(
           ^^^^^^^^^^^^^^^^^^^^^^^^^^^^^^
  File "C:\aqua\firestone-lab\venv\Lib\site-packages\aiohttp\connector.py", line 548, in connect
    proto = await self._create_connection(req, traces, timeout)
            ^^^^^^^^^^^^^^^^^^^^^^^^^^^^^^^^^^^^^^^^^^^^^^^^^^^
  File "C:\aqua\firestone-lab\venv\Lib\site-packages\aiohttp\connector.py", line 1056, in _create_connection
    _, proto = await self._create_direct_connection(req, traces, timeout)
               ^^^^^^^^^^^^^^^^^^^^^^^^^^^^^^^^^^^^^^^^^^^^^^^^^^^^^^^^^^
  File "C:\aqua\firestone-lab\venv\Lib\site-packages\aiohttp\connector.py", line 1414, in _create_direct_connection
    raise last_exc
  File "C:\aqua\firestone-lab\venv\Lib\site-packages\aiohttp\connector.py", line 1383, in _create_direct_connection
    transp, proto = await self._wrap_create_connection(
                    ^^^^^^^^^^^^^^^^^^^^^^^^^^^^^^^^^^^
  File "C:\aqua\firestone-lab\venv\Lib\site-packages\aiohttp\connector.py", line 1135, in _wrap_create_connection
    raise client_error(req.connection_key, exc) from exc
aiohttp.client_exceptions.ClientConnectorError: Cannot connect to host 82.push2.eastmoney.com:443 ssl:default [The semaphore timeout period has expired]
[2025-03-21 14:47:09] ERROR:__main__:Cannot connect to host 82.push2.eastmoney.com:443 ssl:default [The semaphore timeout period has expired]
Traceback (most recent call last):
  File "C:\aqua\firestone-lab\venv\Lib\site-packages\aiohttp\connector.py", line 1116, in _wrap_create_connection
    sock = await aiohappyeyeballs.start_connection(
           ^^^^^^^^^^^^^^^^^^^^^^^^^^^^^^^^^^^^^^^^
  File "C:\aqua\firestone-lab\venv\Lib\site-packages\aiohappyeyeballs\impl.py", line 122, in start_connection
    raise first_exception
  File "C:\aqua\firestone-lab\venv\Lib\site-packages\aiohappyeyeballs\impl.py", line 73, in start_connection
    sock = await _connect_sock(
           ^^^^^^^^^^^^^^^^^^^^
  File "C:\aqua\firestone-lab\venv\Lib\site-packages\aiohappyeyeballs\impl.py", line 208, in _connect_sock
    await loop.sock_connect(sock, address)
  File "C:\Users\BenjaminLi\AppData\Local\Programs\Python\Python312\Lib\asyncio\proactor_events.py", line 729, in sock_connect
    return await self._proactor.connect(sock, address)
           ^^^^^^^^^^^^^^^^^^^^^^^^^^^^^^^^^^^^^^^^^^^
  File "C:\Users\BenjaminLi\AppData\Local\Programs\Python\Python312\Lib\asyncio\windows_events.py", line 803, in _poll
    value = callback(transferred, key, ov)
            ^^^^^^^^^^^^^^^^^^^^^^^^^^^^^^
  File "C:\Users\BenjaminLi\AppData\Local\Programs\Python\Python312\Lib\asyncio\windows_events.py", line 599, in finish_connect
    ov.getresult()
OSError: [WinError 121] The semaphore timeout period has expired

The above exception was the direct cause of the following exception:

Traceback (most recent call last):
  File "C:\aqua\firestone-lab\src\app.py", line 29, in <module>
    if self.base.is_trade_enable():
                            ^^^^^^^^
  File "C:\aqua\firestone-lab\venv\Lib\site-packages\akshare\stock_a\stock_zh_a_spot.py", line 229, in stock_zh_a_spot_em
    return asyncio.run(stock_zh_a_spot_em_async())
           ^^^^^^^^^^^^^^^^^^^^^^^^^^^^^^^^^^^^^^^
  File "C:\Users\BenjaminLi\AppData\Local\Programs\Python\Python312\Lib\asyncio\runners.py", line 194, in run
    return runner.run(main)
           ^^^^^^^^^^^^^^^^
  File "C:\Users\BenjaminLi\AppData\Local\Programs\Python\Python312\Lib\asyncio\runners.py", line 118, in run
    return self._loop.run_until_complete(task)
           ^^^^^^^^^^^^^^^^^^^^^^^^^^^^^^^^^^^
  File "C:\Users\BenjaminLi\AppData\Local\Programs\Python\Python312\Lib\asyncio\base_events.py", line 687, in run_until_complete
    return future.result()
           ^^^^^^^^^^^^^^^
  File "C:\aqua\firestone-lab\venv\Lib\site-packages\akshare\stock_a\stock_zh_a_spot.py", line 218, in stock_zh_a_spot_em_async
    results = await fetch_all_pages_async(url, params)
              ^^^^^^^^^^^^^^^^^^^^^^^^^^^^^^^^^^^^^^^^
  File "C:\aqua\firestone-lab\venv\Lib\site-packages\akshare\stock_a\stock_zh_a_spot.py", line 53, in fetch_all_pages_async
    results = await asyncio.gather(*tasks)
              ^^^^^^^^^^^^^^^^^^^^^^^^^^^^
  File "C:\aqua\firestone-lab\venv\Lib\site-packages\akshare\stock_a\stock_zh_a_spot.py", line 21, in fetch_single_page
    async with session.get(url, params=params) as response:
  File "C:\aqua\firestone-lab\venv\Lib\site-packages\aiohttp\client.py", line 1425, in __aenter__
    self._resp: _RetType = await self._coro
                           ^^^^^^^^^^^^^^^^
  File "C:\aqua\firestone-lab\venv\Lib\site-packages\aiohttp\client.py", line 703, in _request
    conn = await self._connector.connect(
           ^^^^^^^^^^^^^^^^^^^^^^^^^^^^^^
  File "C:\aqua\firestone-lab\venv\Lib\site-packages\aiohttp\connector.py", line 548, in connect
    proto = await self._create_connection(req, traces, timeout)
            ^^^^^^^^^^^^^^^^^^^^^^^^^^^^^^^^^^^^^^^^^^^^^^^^^^^
  File "C:\aqua\firestone-lab\venv\Lib\site-packages\aiohttp\connector.py", line 1056, in _create_connection
    _, proto = await self._create_direct_connection(req, traces, timeout)
               ^^^^^^^^^^^^^^^^^^^^^^^^^^^^^^^^^^^^^^^^^^^^^^^^^^^^^^^^^^
  File "C:\aqua\firestone-lab\venv\Lib\site-packages\aiohttp\connector.py", line 1414, in _create_direct_connection
    raise last_exc
  File "C:\aqua\firestone-lab\venv\Lib\site-packages\aiohttp\connector.py", line 1383, in _create_direct_connection
    transp, proto = await self._wrap_create_connection(
                    ^^^^^^^^^^^^^^^^^^^^^^^^^^^^^^^^^^^
  File "C:\aqua\firestone-lab\venv\Lib\site-packages\aiohttp\connector.py", line 1135, in _wrap_create_connection
    raise client_error(req.connection_key, exc) from exc
aiohttp.client_exceptions.ClientConnectorError: Cannot connect to host 82.push2.eastmoney.com:443 ssl:default [The semaphore timeout period has expired]
